============================= test session starts ==============================
platform linux -- Python 3.9.14, pytest-7.1.3, pluggy-1.0.0
rootdir: /workspace
collected 14 items
tests/test_a_environment.py .                                            [  7%]
tests/test_a_setup.py .                                                  [ 14%]
tests/test_distances.py ...                                              [ 35%]
tests/test_generate_regression_data.py .                                 [ 42%]
tests/test_knn.py .F...                                                  [ 78%]
tests/test_metrics.py .                                                  [ 85%]
tests/test_polynomial_regression.py ..                                   [100%]
=================================== FAILURES ===================================
_______________________________ test_knn_k_is_1 ________________________________
>                   accuracy = run(datasets[key], fraction,
                                   n_neighbors=1,
                                   distance_measure=distance_measure,
                                   aggregator="mode")
tests/test_knn.py:66:
>           return bound(*args, **kwds)
E           ValueError: attempt to get argmax of an empty sequence
/usr/local/lib/python3.9/site-packages/numpy/core/fromnumeric.py:57: ValueError
=============================== warnings summary ===============================
tests/test_knn.py::test_knn_k_is_1
  /workspace/src/distances.py:76: RuntimeWarning: invalid value encountered in double_scalars
    S = upper/down
-- Docs: https://docs.pytest.org/en/stable/how-to/capture-warnings.html
=========================== short test summary info ============================
FAILED tests/test_knn.py::test_knn_k_is_1 - ValueError: attempt to get argmax...
=================== 1 failed, 13 passed, 1 warning in 7.20s ====================